<?xml version="1.0" ?>
<robot name="robo_arm" xmlns:xacro="http://ros.org/wiki/xacro">

<gazebo>
  <plugin name="gazebo_ros_control" filename="gazebo_ros_control.so">
    <robotNamespace>Manipulator</robotNamespace>
  </plugin>
</gazebo>

<gazebo reference="base_link">
  <material>Gazebo/Black</material>
</gazebo>

<gazebo reference="arm_link_0">
  <material>Gazebo/Orange</material>
</gazebo>

<gazebo reference="arm_link_1">
  <material>Gazebo/Blue</material>
</gazebo>

<gazebo reference="arm_link_2">
  <material>Gazebo/Orange</material>
</gazebo>

<gazebo reference="arm_link_3">
  <material>Gazebo/Blue</material>
</gazebo>

<gazebo reference="arm_link_4">
  <material>Gazebo/Orange</material>
</gazebo>

<gazebo reference="arm_link_5">
  <material>Gazebo/Blue</material>
</gazebo>

<gazebo reference="arm_link_6">
  <material>Gazebo/Orange</material>
</gazebo>

<gazebo reference="arm_link_7">
  <material>Gazebo/Blue</material>
</gazebo>

<gazebo reference="arm_link_8">
  <material>Gazebo/Blue</material>
</gazebo>

<!--Colors for the shapes-->
  <material name="omni/Blue">
    <color rgba="0 0 0.8 1"/>
  </material>
  <material name="omni/Red">
    <color rgba="1 0 0 1"/>
  </material>
  <material name="omni/Green">
    <color rgba="0 1 0 1"/>
  </material>
  <material name="omni/Yellow">
    <color rgba="1 1 0 1"/>
  </material>
  <material name="omni/LightGrey">
    <color rgba="0.6 0.6 0.6 1"/>
  </material>
  <material name="omni/DarkGrey">
    <color rgba="0.4 0.4 0.4 1"/>
  </material>
<!--Base link -->
  <link name="base_link">
    <inertial>
      <origin rpy="0 0 0" xyz="0 0 0"/>
      <mass value="10.0"/>
      <inertia ixx="0.1" ixy="0" ixz="0" iyy="0.1" iyz="0" izz="0.1"/>
    </inertial>
  </link>
  <!-- joint between base_link and arm_0_link -->
  <joint name="arm_joint_0" type="fixed">
    <origin rpy="0 0 0" xyz="0 0 0"/>
    <parent link="base_link"/>
    <child link="arm_link_0"/>
  </joint>
  <link name="arm_link_0">
    <visual>
      <origin rpy="0 0 0" xyz="0 0 0.02725"/>
      <geometry>
        <box size="0.1143 0.1143 0.0545"/>
      </geometry>
      <material name="omni/LightGrey"/>
    </visual>
    <collision>
      <origin rpy="0 0 0" xyz="0 0 0.02725"/>
      <geometry>
        <box size="0.1143 0.1143 0.0545"/>
      </geometry>
    </collision>
    <inertial>
      <!-- CENTER OF MASS -->
      <origin rpy="0 0 0" xyz="0 0 0.02725"/>
      <mass value="0.2"/>
      <!-- box inertia: 1/12*m(y^2+z^2), ... -->
      <inertia ixx="0.000267245666667" ixy="0" ixz="0" iyy="0.000267245666667" iyz="0" izz="0.000435483"/>
    </inertial>
  </link>
  <joint name="arm_joint_1" type="revolute">
    <parent link="arm_link_0"/>
    <child link="arm_link_1"/>
    <dynamics damping="3.0" friction="0.3"/>
    <limit effort="30.0" lower="-3.1415926535" upper="3.1415926535" velocity="5.0"/>
    <origin rpy="0 0 0" xyz="0 0 0.0545"/>
    <axis xyz="0 0 1"/>
  </joint>
  <link name="arm_link_1">
    <visual>
      <origin rpy="0 0 0" xyz="0 0 0.011"/>
      <geometry>
        <box size="0.0402 0.05 0.023"/>
      </geometry>
      <material name="omni/Blue"/>
    </visual>
    <collision>
      <origin rpy="0 0 0" xyz="0 0 0.011"/>
      <geometry>
        <box size="0.0402 0.05 0.023"/>
      </geometry>
    </collision>
    <inertial>
      <!-- CENTER OF MASS -->
      <origin rpy="0 0 0" xyz="0 0 0.0615"/>
      <mass value="0.190421352"/>
      <!-- box inertia: 1/12*m(y^2+z^2), ... -->
      <inertia ixx="0.000279744834534" ixy="0" ixz="0" iyy="0.000265717763008" iyz="0" izz="6.53151584738e-05"/>
    </inertial>
  </link>
  <joint name="arm_joint_2" type="revolute">
    <parent link="arm_link_1"/>
    <child link="arm_link_2"/>
    <dynamics damping="3.0" friction="0.3"/>
    <limit effort="30.0" lower="0" upper="1.57079632679" velocity="5.0"/>
    <origin rpy="0 0 0" xyz="0 0 0.02"/>
    <axis xyz="0 1 0"/>
  </joint>
  <link name="arm_link_2">
    <visual>
      <origin rpy="0 0 0" xyz="0 0 0.222"/>
      <geometry>
        <box size="0.0356 0.05 0.44"/>
      </geometry>
      <material name="omni/Red"/>
    </visual>
    <collision>
      <origin rpy="0 0 0" xyz="0 0 0.222"/>
      <geometry>
        <box size="0.0356 0.05 0.44"/>
      </geometry>
    </collision>
    <inertial>
      <!-- CENTER OF MASS -->
      <origin rpy="0 0 0" xyz="0 0 0.1585"/>
      <mass value="0.29302326"/>
      <!-- box inertia: 1/12*m(y^2+z^2), ... -->
      <inertia ixx="0.00251484771035" ixy="0" ixz="0" iyy="0.00248474836108" iyz="0" izz="9.19936757328e-05"/>
    </inertial>
  </link>
  <joint name="arm_joint_3" type="revolute">
    <parent link="arm_link_2"/>
    <child link="arm_link_3"/>
    <dynamics damping="3.0" friction="0.3"/>
    <limit effort="30.0" lower="0" upper="1.57079632679" velocity="5.0"/>
    <origin rpy="0 0 0" xyz="0 0 0.5"/>
    <axis xyz="0 1 0"/>
  </joint>
  <link name="arm_link_3">
    <visual>
      <origin rpy="0 0 0" xyz="0 0 0.13"/>
      <geometry>
        <box size="0.0356 0.05 0.375"/>
      </geometry>
      <material name="omni/Yellow"/>
    </visual>
    <collision>
      <origin rpy="0 0 0" xyz="0 0 0.13"/>
      <geometry>
        <box size="0.0356 0.05 0.375"/>
      </geometry>
    </collision>
    <inertial>
      <!-- CENTER OF MASS -->
      <origin rpy="0 0 0" xyz="0 0 0.101"/>
      <mass value="0.21931466"/>
      <!-- box inertia: 1/12*m(y^2+z^2), ... -->
      <inertia ixx="0.000791433503053" ixy="0" ixz="0" iyy="0.000768905501178" iyz="0" izz="6.88531064581e-05"/>
    </inertial>
  </link>
  <joint name="arm_joint_4" type="revolute">
    <parent link="arm_link_3"/>
    <child link="arm_link_4"/>
    <dynamics damping="3.0" friction="0.3"/>
    <limit effort="30.0" lower="-1.5707963268" upper="1.5707963268" velocity="5.0"/>
    <origin rpy="0 0 0" xyz="0 0 0.317"/>
    <axis xyz="0 1 0"/>
  </joint>
  <link name="arm_link_4">
    <visual>
      <origin rpy="0 0 0" xyz="0 0 0.028"/>
      <geometry>
        <box size="0.0402 0.05 0.056"/>
      </geometry>
      <material name="omni/Blue"/>
    </visual>
    <collision>
      <origin rpy="0 0 0" xyz="0 0 0"/>
      <geometry>
        <box size="0.0402 0.05 0.056"/>
      </geometry>
    </collision>
    <inertial>
      <!-- CENTER OF MASS -->
      <origin rpy="0 0 0" xyz="0 0 0.0615"/>
      <mass value="0.190421352"/>
      <!-- box inertia: 1/12*m(y^2+z^2), ... -->
      <inertia ixx="0.000279744834534" ixy="0" ixz="0" iyy="0.000265717763008" iyz="0" izz="6.53151584738e-05"/>
    </inertial>
  </link>
  <joint name="arm_joint_5" type="revolute">
    <parent link="arm_link_4"/>
    <child link="arm_link_5"/>
    <dynamics damping="3.0" friction="0.3"/>
    <limit effort="30.0" lower="-3.1415926535" upper="3.1415926535" velocity="5.0"/>
    <origin rpy="0 0 0" xyz="0 0 0.05"/>
    <axis xyz="0 0 1"/>
  </joint>
  <link name="arm_link_5">
    <visual>
      <origin rpy="0 0 0" xyz="0 0 0.012"/>
      <geometry>
        <box size="0.0402 0.05 0.010"/>
      </geometry>
      <material name="omni/Red"/>
    </visual>
    <collision>
      <origin rpy="0 0 0" xyz="0 0 0"/>
      <geometry>
        <box size="0.0402 0.05 0.010"/>
      </geometry>
    </collision>
    <inertial>
      <!-- CENTER OF MASS -->
      <origin rpy="0 0 0" xyz="0 0 0.0615"/>
      <mass value="0.190421352"/>
      <!-- box inertia: 1/12*m(y^2+z^2), ... -->
      <inertia ixx="0.000279744834534" ixy="0" ixz="0" iyy="0.000265717763008" iyz="0" izz="6.53151584738e-05"/>
    </inertial>
  </link>
  <joint name="arm_joint_6" type="fixed">
    <origin rpy="0 0 0" xyz="0 0 0"/>
    <parent link="arm_link_5"/>
    <child link="arm_link_6"/>
  </joint>
  <link name="arm_link_6">
    <visual>
      <origin rpy="0 0 0" xyz="0 0 0.023"/>
      <geometry>
        <box size="0.0402 0.05 0.010"/>
      </geometry>
      <material name="omni/LightGrey"/>
    </visual>
    <collision>
      <origin rpy="0 0 0" xyz="0 0 0.02725"/>
      <geometry>
        <box size="0.0402 0.05 0.010"/>
      </geometry>
    </collision>
    <inertial>
      <!-- CENTER OF MASS -->
      <origin rpy="0 0 0" xyz="0 0 0.02725"/>
      <mass value="0.2"/>
      <!-- box inertia: 1/12*m(y^2+z^2), ... -->
      <inertia ixx="0.000267245666667" ixy="0" ixz="0" iyy="0.000267245666667" iyz="0" izz="0.000435483"/>
    </inertial>
  </link>
  <joint name="arm_joint_7" type="revolute">
    <parent link="arm_link_6"/>
    <child link="arm_link_7"/>
    <dynamics damping="3.0" friction="0.3"/>
    <limit effort="30.0" lower="0" upper="1.0471975512" velocity="5.0"/>
    <origin rpy="0 0 0" xyz="0.01 0 0.0275"/>
    <axis xyz="0 1 0"/>
  </joint>
  <link name="arm_link_7">
    <visual>
      <origin rpy="0 0 0" xyz="0 0 0.035"/>
      <geometry>
        <box size="0.0201 0.04 0.07"/>
      </geometry>
      <material name="omni/Blue"/>
    </visual>
    <collision>
      <origin rpy="0 0 0" xyz="0 0 0"/>
      <geometry>
        <box size="0.0402 0.05 0.010"/>
      </geometry>
    </collision>
    <inertial>
      <!-- CENTER OF MASS -->
      <origin rpy="0 0 0" xyz="0 0 0.0615"/>
      <mass value="0.190421352"/>
      <!-- box inertia: 1/12*m(y^2+z^2), ... -->
      <inertia ixx="0.000279744834534" ixy="0" ixz="0" iyy="0.000265717763008" iyz="0" izz="6.53151584738e-05"/>
    </inertial>
  </link>
  <joint name="arm_joint_8" type="revolute">
    <parent link="arm_link_6"/>
    <child link="arm_link_8"/>
    <dynamics damping="3.0" friction="0.3"/>
    <limit effort="30.0" lower="0" upper="1.0471975512" velocity="5.0"/>
    <origin rpy="0 0 0" xyz="-0.01 0 0.0275"/>
    <axis xyz="0 -1 0"/>
  </joint>
  <link name="arm_link_8">
    <visual>
      <origin rpy="0 0 0" xyz="0 0 0.035"/>
      <geometry>
        <box size="0.0201 0.04 0.07"/>
      </geometry>
      <material name="omni/Blue"/>
    </visual>
    <collision>
      <origin rpy="0 0 0" xyz="0 0 0"/>
      <geometry>
        <box size="0.0402 0.05 0.010"/>
      </geometry>
    </collision>
    <inertial>
      <!-- CENTER OF MASS -->
      <origin rpy="0 0 0" xyz="0 0 0.0615"/>
      <mass value="0.190421352"/>
      <!-- box inertia: 1/12*m(y^2+z^2), ... -->
      <inertia ixx="0.000279744834534" ixy="0" ixz="0" iyy="0.000265717763008" iyz="0" izz="6.53151584738e-05"/>
    </inertial>
  </link>
</robot>